Workbook

Sheet Inputs
A1: INPUTS — All Blue Cells Are Editable
A3: CAPITAL & PARAMETERS
A4: Parameter | B4: Value | C4: Notes
A5: AUM (THB mn) | B5: 8000 | C5: Total investable portfolio
A6: Non-Listed % (bolt-on) | B6: 0.048 | C6: Fixed 4.8% — not in optimization
A7: TCA (THB mn) | B7: 2091 | C7: Total Capital Available
A8: TCR_Insurance (mn) | B8: 622.5 | C8: Fixed insurance risk component
A9: Risk-Free Rate (Rf) | B9: 0.0125 | C9: For Sharpe ratio
A10: VaR Z-score (99.5%) | B10: 2.576 | C10: Parametric confidence level
A11: OIC Min CAR | B11: 1.4 | C11: Regulatory floor
A12: Trading Days/yr | B12: 252 | C12: For daily SD conversion
A14: CAPITAL MARKET ASSUMPTIONS — 7 Investable Assets (GSAM/KKP Feb 2026)
A15: Asset | B15: Return % | C15: Annual SD % | D15: Sharpe | E15: RBC % | F15: IFRS | G15: VaR Method | H15: Note
A16: Cash & MMF | B16: 0.013 | C16: 0 | E16: 0.002
A17: Gov Bonds | B17: 0.013 | C17: 0.01 | D17: 0.09 | E17: 0.046 | F17: OCI (FVOCI) | G17: DV01
A18: Corp Bonds | B18: 0.013 | C18: 0.008 | D18: 0.1 | E18: 0.0455 | F18: OCI (FVOCI) | G18: DV01
A19: Global FI | B19: 0.03 | C19: 0.056 | D19: 0.32 | E19: 0.059 | F19: P&L (FVPL via fund) | G19: SD-based
A20: Local REIT | B20: 0.058 | C20: 0.135 | D20: 0.34 | E20: 0.16 | F20: P&L (FVPL) | G20: SD-based
A21: Local Equity | B21: 0.043 | C21: 0.17 | D21: 0.18 | E21: 0.18 | F21: P&L (FVPL) | G21: SD-based
A22: Global Equity | B22: 0.075 | C22: 0.166 | D22: 0.38 | E22: 0.25 | F22: P&L (FVPL) | G22: SD-based
A23: Non-Listed Equity [bolt-on] | B23: 0.00% | C23: 0.00% | D23: n/a | E23: 0.00% | F23: Excluded (not IFRS classified) | G23: None | H23: Return=Risk=RBC=VaR=0
A25: OCI VaR PARAMETERS — DV01 (Gov & Corp only)
A26: Asset | B26: Duration (yr) | C26: Yield Vol (bps/yr) | D26: Yield Vol (decimal) | E26: Note
A27: Gov Bonds | B27: 4 | C27: 45 | D27: =C27/10000 -> 0.0045 | E27: Row 17 in CME
A28: Corp Bonds | B28: 2 | C28: 40 | D28: =C28/10000 -> 0.004 | E28: Row 18 in CME
A30: CORRELATION MATRIX 7×7 (GSAM Feb 2026, p.43)
B31: Cash | C31: Gov | D31: Corp | E31: GloFI | F31: REIT | G31: LocEq | H31: GloEq
A32: Cash | B32: 1 | C32: 0 | D32: 0 | E32: 0 | F32: 0 | G32: 0 | H32: 0
A33: Gov | B33: 0 | C33: 1 | D33: 0.58 | E33: 0.11 | F33: 0.17 | G33: 0.02 | H33: 0.09
A34: Corp | B34: 0 | C34: 0.58 | D34: 1 | E34: 0.1 | F34: 0.15 | G34: 0.06 | H34: 0.14
A35: GloFI | B35: 0 | C35: 0.11 | D35: 0.1 | E35: 1 | F35: 0.3 | G35: 0.01 | H35: 0.26
A36: REIT | B36: 0 | C36: 0.17 | D36: 0.15 | E36: 0.3 | F36: 1 | G36: 0.64 | H36: 0.44
A37: LocEq | B37: 0 | C37: 0.02 | D37: 0.06 | E37: 0.01 | F37: 0.64 | G37: 1 | H37: 0.45
A38: GloEq | B38: 0 | C38: 0.09 | D38: 0.14 | E38: 0.26 | F38: 0.44 | G38: 0.45 | H38: 1

Sheet Calc
A1: Calc Engine — COV Matrix & Helper Calculations
A3: Covariance Matrix (daily) — COV[i][j] = SD_daily_i × SD_daily_j × corr[i][j]
B4: Cash | C4: Gov | D4: Corp | E4: GloFI | F4: REIT | G4: LocEq | H4: GloEq
A5: Cash | B5: =(Inputs!C16/SQRT(Inputs!B12))*(Inputs!C16/SQRT(Inputs!B12))*Inputs!B32 -> 0 | C5: =(Inputs!C16/SQRT(Inputs!B12))*(Inputs!C17/SQRT(Inputs!B12))*Inputs!C32 -> 0 | D5: =(Inputs!C16/SQRT(Inputs!B12))*(Inputs!C18/SQRT(Inputs!B12))*Inputs!D32 -> 0 | E5: =(Inputs!C16/SQRT(Inputs!B12))*(Inputs!C19/SQRT(Inputs!B12))*Inputs!E32 -> 0 | F5: =(Inputs!C16/SQRT(Inputs!B12))*(Inputs!C20/SQRT(Inputs!B12))*Inputs!F32 -> 0 | G5: =(Inputs!C16/SQRT(Inputs!B12))*(Inputs!C21/SQRT(Inputs!B12))*Inputs!G32 -> 0 | H5: =(Inputs!C16/SQRT(Inputs!B12))*(Inputs!C22/SQRT(Inputs!B12))*Inputs!H32 -> 0
A6: Gov | B6: =(Inputs!C17/SQRT(Inputs!B12))*(Inputs!C16/SQRT(Inputs!B12))*Inputs!B33 -> 0 | C6: =(Inputs!C17/SQRT(Inputs!B12))*(Inputs!C17/SQRT(Inputs!B12))*Inputs!C33 -> 3.968254e-07 | D6: =(Inputs!C17/SQRT(Inputs!B12))*(Inputs!C18/SQRT(Inputs!B12))*Inputs!D33 -> 1.8412698e-07 | E6: =(Inputs!C17/SQRT(Inputs!B12))*(Inputs!C19/SQRT(Inputs!B12))*Inputs!E33 -> 2.4444444e-07 | F6: =(Inputs!C17/SQRT(Inputs!B12))*(Inputs!C20/SQRT(Inputs!B12))*Inputs!F33 -> 9.1071429e-07 | G6: =(Inputs!C17/SQRT(Inputs!B12))*(Inputs!C21/SQRT(Inputs!B12))*Inputs!G33 -> 1.3492063e-07 | H6: =(Inputs!C17/SQRT(Inputs!B12))*(Inputs!C22/SQRT(Inputs!B12))*Inputs!H33 -> 5.9285714e-07
A7: Corp | B7: =(Inputs!C18/SQRT(Inputs!B12))*(Inputs!C16/SQRT(Inputs!B12))*Inputs!B34 -> 0 | C7: =(Inputs!C18/SQRT(Inputs!B12))*(Inputs!C17/SQRT(Inputs!B12))*Inputs!C34 -> 1.8412698e-07 | D7: =(Inputs!C18/SQRT(Inputs!B12))*(Inputs!C18/SQRT(Inputs!B12))*Inputs!D34 -> 2.5396825e-07 | E7: =(Inputs!C18/SQRT(Inputs!B12))*(Inputs!C19/SQRT(Inputs!B12))*Inputs!E34 -> 1.7777778e-07 | F7: =(Inputs!C18/SQRT(Inputs!B12))*(Inputs!C20/SQRT(Inputs!B12))*Inputs!F34 -> 6.4285714e-07 | G7: =(Inputs!C18/SQRT(Inputs!B12))*(Inputs!C21/SQRT(Inputs!B12))*Inputs!G34 -> 3.2380952e-07 | H7: =(Inputs!C18/SQRT(Inputs!B12))*(Inputs!C22/SQRT(Inputs!B12))*Inputs!H34 -> 7.3777778e-07
A8: GloFI | B8: =(Inputs!C19/SQRT(Inputs!B12))*(Inputs!C16/SQRT(Inputs!B12))*Inputs!B35 -> 0 | C8: =(Inputs!C19/SQRT(Inputs!B12))*(Inputs!C17/SQRT(Inputs!B12))*Inputs!C35 -> 2.4444444e-07 | D8: =(Inputs!C19/SQRT(Inputs!B12))*(Inputs!C18/SQRT(Inputs!B12))*Inputs!D35 -> 1.7777778e-07 | E8: =(Inputs!C19/SQRT(Inputs!B12))*(Inputs!C19/SQRT(Inputs!B12))*Inputs!E35 -> 1.2444444e-05 | F8: =(Inputs!C19/SQRT(Inputs!B12))*(Inputs!C20/SQRT(Inputs!B12))*Inputs!F35 -> 9e-06 | G8: =(Inputs!C19/SQRT(Inputs!B12))*(Inputs!C21/SQRT(Inputs!B12))*Inputs!G35 -> 3.7777778e-07 | H8: =(Inputs!C19/SQRT(Inputs!B12))*(Inputs!C22/SQRT(Inputs!B12))*Inputs!H35 -> 9.5911111e-06
A9: REIT | B9: =(Inputs!C20/SQRT(Inputs!B12))*(Inputs!C16/SQRT(Inputs!B12))*Inputs!B36 -> 0 | C9: =(Inputs!C20/SQRT(Inputs!B12))*(Inputs!C17/SQRT(Inputs!B12))*Inputs!C36 -> 9.1071429e-07 | D9: =(Inputs!C20/SQRT(Inputs!B12))*(Inputs!C18/SQRT(Inputs!B12))*Inputs!D36 -> 6.4285714e-07 | E9: =(Inputs!C20/SQRT(Inputs!B12))*(Inputs!C19/SQRT(Inputs!B12))*Inputs!E36 -> 9e-06 | F9: =(Inputs!C20/SQRT(Inputs!B12))*(Inputs!C20/SQRT(Inputs!B12))*Inputs!F36 -> 7.2321429e-05 | G9: =(Inputs!C20/SQRT(Inputs!B12))*(Inputs!C21/SQRT(Inputs!B12))*Inputs!G36 -> 5.8285714e-05 | H9: =(Inputs!C20/SQRT(Inputs!B12))*(Inputs!C22/SQRT(Inputs!B12))*Inputs!H36 -> 3.9128571e-05
A10: LocEq | B10: =(Inputs!C21/SQRT(Inputs!B12))*(Inputs!C16/SQRT(Inputs!B12))*Inputs!B37 -> 0 | C10: =(Inputs!C21/SQRT(Inputs!B12))*(Inputs!C17/SQRT(Inputs!B12))*Inputs!C37 -> 1.3492063e-07 | D10: =(Inputs!C21/SQRT(Inputs!B12))*(Inputs!C18/SQRT(Inputs!B12))*Inputs!D37 -> 3.2380952e-07 | E10: =(Inputs!C21/SQRT(Inputs!B12))*(Inputs!C19/SQRT(Inputs!B12))*Inputs!E37 -> 3.7777778e-07 | F10: =(Inputs!C21/SQRT(Inputs!B12))*(Inputs!C20/SQRT(Inputs!B12))*Inputs!F37 -> 5.8285714e-05 | G10: =(Inputs!C21/SQRT(Inputs!B12))*(Inputs!C21/SQRT(Inputs!B12))*Inputs!G37 -> 0.00011468254 | H10: =(Inputs!C21/SQRT(Inputs!B12))*(Inputs!C22/SQRT(Inputs!B12))*Inputs!H37 -> 5.0392857e-05
A11: GloEq | B11: =(Inputs!C22/SQRT(Inputs!B12))*(Inputs!C16/SQRT(Inputs!B12))*Inputs!B38 -> 0 | C11: =(Inputs!C22/SQRT(Inputs!B12))*(Inputs!C17/SQRT(Inputs!B12))*Inputs!C38 -> 5.9285714e-07 | D11: =(Inputs!C22/SQRT(Inputs!B12))*(Inputs!C18/SQRT(Inputs!B12))*Inputs!D38 -> 7.3777778e-07 | E11: =(Inputs!C22/SQRT(Inputs!B12))*(Inputs!C19/SQRT(Inputs!B12))*Inputs!E38 -> 9.5911111e-06 | F11: =(Inputs!C22/SQRT(Inputs!B12))*(Inputs!C20/SQRT(Inputs!B12))*Inputs!F38 -> 3.9128571e-05 | G11: =(Inputs!C22/SQRT(Inputs!B12))*(Inputs!C21/SQRT(Inputs!B12))*Inputs!G38 -> 5.0392857e-05 | H11: =(Inputs!C22/SQRT(Inputs!B12))*(Inputs!C22/SQRT(Inputs!B12))*Inputs!H38 -> 0.00010934921
A14: Inner products: inner[i] = Σj wj×COV[i][j] per scenario (for portfolio variance) | B14: Current SAA | C14: Port 1 | D14: Port 2 | E14: Port 3 | F14: Port 4 | G14: Custom
B15: =SUMPRODUCT(Dashboard!C6:C12,Calc!B5:B11) -> 0 | C15: =SUMPRODUCT(Dashboard!D6:D12,Calc!B5:B11) -> 0 | D15: =SUMPRODUCT(Dashboard!E6:E12,Calc!B5:B11) -> 0 | E15: =SUMPRODUCT(Dashboard!F6:F12,Calc!B5:B11) -> 0 | F15: =SUMPRODUCT(Dashboard!G6:G12,Calc!B5:B11) -> 0 | G15: =SUMPRODUCT(Dashboard!H6:H12,Calc!B5:B11) -> 0
B16: =SUMPRODUCT(Dashboard!C6:C12,Calc!C5:C11) -> 2.9818452e-07 | C16: =SUMPRODUCT(Dashboard!D6:D12,Calc!C5:C11) -> 2.9040794e-07 | D16: =SUMPRODUCT(Dashboard!E6:E12,Calc!C5:C11) -> 2.9330317e-07 | E16: =SUMPRODUCT(Dashboard!F6:F12,Calc!C5:C11) -> 3.056369e-07 | F16: =SUMPRODUCT(Dashboard!G6:G12,Calc!C5:C11) -> 3.0285317e-07 | G16: =SUMPRODUCT(Dashboard!H6:H12,Calc!C5:C11) -> 2.9040794e-07
B17: =SUMPRODUCT(Dashboard!C6:C12,Calc!D5:D11) -> 1.9816349e-07 | C17: =SUMPRODUCT(Dashboard!D6:D12,Calc!D5:D11) -> 2.3037841e-07 | D17: =SUMPRODUCT(Dashboard!E6:E12,Calc!D5:D11) -> 2.2672127e-07 | E17: =SUMPRODUCT(Dashboard!F6:F12,Calc!D5:D11) -> 2.1393492e-07 | F17: =SUMPRODUCT(Dashboard!G6:G12,Calc!D5:D11) -> 2.1924127e-07 | G17: =SUMPRODUCT(Dashboard!H6:H12,Calc!D5:D11) -> 2.3037841e-07
B18: =SUMPRODUCT(Dashboard!C6:C12,Calc!E5:E11) -> 4.018e-07 | C18: =SUMPRODUCT(Dashboard!D6:D12,Calc!E5:E11) -> 8.1881778e-07 | D18: =SUMPRODUCT(Dashboard!E6:E12,Calc!E5:E11) -> 1.4076178e-06 | E18: =SUMPRODUCT(Dashboard!F6:F12,Calc!E5:E11) -> 6.814e-07 | F18: =SUMPRODUCT(Dashboard!G6:G12,Calc!E5:E11) -> 7.4068889e-07 | G18: =SUMPRODUCT(Dashboard!H6:H12,Calc!E5:E11) -> 8.1881778e-07
B19: =SUMPRODUCT(Dashboard!C6:C12,Calc!F5:F11) -> 3.2933571e-06 | C19: =SUMPRODUCT(Dashboard!D6:D12,Calc!F5:F11) -> 4.5505286e-06 | D19: =SUMPRODUCT(Dashboard!E6:E12,Calc!F5:F11) -> 4.9516714e-06 | E19: =SUMPRODUCT(Dashboard!F6:F12,Calc!F5:F11) -> 4.0956429e-06 | F19: =SUMPRODUCT(Dashboard!G6:G12,Calc!F5:F11) -> 4.5874821e-06 | G19: =SUMPRODUCT(Dashboard!H6:H12,Calc!F5:F11) -> 4.5505286e-06
B20: =SUMPRODUCT(Dashboard!C6:C12,Calc!G5:G11) -> 3.347381e-06 | C20: =SUMPRODUCT(Dashboard!D6:D12,Calc!G5:G11) -> 4.9167238e-06 | D20: =SUMPRODUCT(Dashboard!E6:E12,Calc!G5:G11) -> 4.9193143e-06 | E20: =SUMPRODUCT(Dashboard!F6:F12,Calc!G5:G11) -> 4.1678333e-06 | F20: =SUMPRODUCT(Dashboard!G6:G12,Calc!G5:G11) -> 4.5805556e-06 | G20: =SUMPRODUCT(Dashboard!H6:H12,Calc!G5:G11) -> 4.9167238e-06
B21: =SUMPRODUCT(Dashboard!C6:C12,Calc!H5:H11) -> 2.256019e-06 | C21: =SUMPRODUCT(Dashboard!D6:D12,Calc!H5:H11) -> 7.0796892e-06 | D21: =SUMPRODUCT(Dashboard!E6:E12,Calc!H5:H11) -> 7.5046492e-06 | E21: =SUMPRODUCT(Dashboard!F6:F12,Calc!H5:H11) -> 5.2199095e-06 | F21: =SUMPRODUCT(Dashboard!G6:G12,Calc!H5:H11) -> 5.4940071e-06 | G21: =SUMPRODUCT(Dashboard!H6:H12,Calc!H5:H11) -> 7.0796892e-06

Sheet Dashboard
A1: ERGO Insurance Thailand — SAA Portfolio Analysis (v5 — All Auto-Calculate)
A2: AUM 8,000mn | TCA 2,091mn | TCR_Ins 622.5mn | Non-Listed 4.8% bolt-on (Return=Risk=RBC=VaR=0) | Investable 95.2% | P&L VaR: GloFI+REIT+LocalEq+GloEq | OCI VaR (DV01): Gov+Corp | ΔTCR = Σ(VaR_standalone × RBC) per asset
A4: A. PORTFOLIO WEIGHTS | Column H = Custom Scenario (edit blue cells)
A5: Asset | B5: RBC Charge | C5: Current SAA | D5: Port 1 | E5: Port 2 | F5: Port 3 | G5: Port 4 | H5: ► Custom (edit here)
A6: Cash & MMF | B6: =Inputs!E16 -> 0.002 | C6: 0.059 | D6: 0.052 | E6: 0.052 | F6: 0.059 | G6: 0.059 | H6: 0.052
A7: Gov Bonds | B7: =Inputs!E17 -> 0.046 | C7: 0.554 | D7: 0.428 | E7: 0.428 | F7: 0.53 | G7: 0.493 | H7: 0.428
A8: Corp Bonds | B8: =Inputs!E18 -> 0.0455 | C8: 0.3 | D8: 0.394 | E8: 0.346 | F8: 0.3 | G8: 0.33 | H8: 0.394
A9: Global FI | B9: =Inputs!E19 -> 0.059 | C9: 0 | D9: 0 | E9: 0.048 | F9: 0 | G9: 0 | H9: 0
A10: Local REIT | B10: =Inputs!E20 -> 0.16 | C10: 0.023 | D10: 0.02 | E10: 0.02 | F10: 0.023 | G10: 0.03 | H10: 0.02
A11: Local Equity | B11: =Inputs!E21 -> 0.18 | C11: 0.016 | D11: 0.01 | E11: 0.01 | F11: 0.01 | G11: 0.01 | H11: 0.01
A12: Global Equity | B12: =Inputs!E22 -> 0.25 | C12: 0 | D12: 0.048 | E12: 0.048 | F12: 0.03 | G12: 0.03 | H12: 0.048
A13: Non-Listed Equity [bolt-on — 4.8% fixed] | B13: 0.00% (RBC=0) | C13: 4.80% | D13: 4.80% | E13: 4.80% | F13: 4.80% | G13: 4.80% | H13: 4.80%
A14: Investable Total | C14: =SUM(C6:C12) -> 0.952 | D14: =SUM(D6:D12) -> 0.952 | E14: =SUM(E6:E12) -> 0.952 | F14: =SUM(F6:F12) -> 0.952 | G14: =SUM(G6:G12) -> 0.952 | H14: =SUM(H6:H12) -> 0.952
H15: =IF(ABS(H14-0.952)<0.002,"✓ 95.2% OK","⚠ Must = 95.2%") -> ✓ 95.2% OK
A17: B. PORTFOLIO METRICS (All formulas — edit weights in column H to update)
A18: Metric | B18: Formula Logic | C18: Current SAA | D18: Port 1 | E18: Port 2 | F18: Port 3 | G18: Port 4 | H18: Custom
A19: Expected Return | B19: SUMPRODUCT(weights, returns) | C19: =SUMPRODUCT(C6:C12,Inputs!B16:B22) -> 0.013891 | D19: =SUMPRODUCT(D6:D12,Inputs!B16:B22) -> 0.016552 | E19: =SUMPRODUCT(E6:E12,Inputs!B16:B22) -> 0.017368 | F19: =SUMPRODUCT(F6:F12,Inputs!B16:B22) -> 0.015571 | G19: =SUMPRODUCT(G6:G12,Inputs!B16:B22) -> 0.015886 | H19: =SUMPRODUCT(H6:H12,Inputs!B16:B22) -> 0.016552
A20: Portfolio Variance (daily) | B20: SUMPRODUCT(w, Σj wj×COVij) — no array formula | C20: =SUMPRODUCT(Dashboard!C6:C12,Calc!B15:B21) -> 3.5394858e-07 | D20: =SUMPRODUCT(Dashboard!D6:D12,Calc!C15:C21) -> 6.9506658e-07 | E20: =SUMPRODUCT(Dashboard!E6:E12,Calc!D15:D21) -> 7.799947e-07 | F20: =SUMPRODUCT(Dashboard!F6:F12,Calc!E15:E21) -> 5.1864344e-07 | G20: =SUMPRODUCT(Dashboard!G6:G12,Calc!F15:F21) -> 5.6990647e-07 | H20: =SUMPRODUCT(H6:H12,Calc!G15:G21) -> 6.9506658e-07
A21: Portfolio SD (Annual) | B21: SQRT(daily_var × 252) | C21: =SQRT(C20*Inputs!B12) -> 0.0094443127 | D21: =SQRT(D20*Inputs!B12) -> 0.013234681 | E21: =SQRT(E20*Inputs!B12) -> 0.014019938 | F21: =SQRT(F20*Inputs!B12) -> 0.011432329 | G21: =SQRT(G20*Inputs!B12) -> 0.011984007 | H21: =SQRT(H20*Inputs!B12) -> 0.013234681
A22: Sharpe Ratio (Rf=1.25%) | B22: (Return − Rf) ÷ Annual SD | C22: =IF(C21>0,(C19-Inputs!B9)/C21,0) -> 0.14728441 | D22: =IF(D21>0,(D19-Inputs!B9)/D21,0) -> 0.3061653 | E22: =IF(E21>0,(E19-Inputs!B9)/E21,0) -> 0.34721979 | F22: =IF(F21>0,(F19-Inputs!B9)/F21,0) -> 0.26862418 | G22: =IF(G21>0,(G19-Inputs!B9)/G21,0) -> 0.28254322 | H22: =IF(H21>0,(H19-Inputs!B9)/H21,0) -> 0.3061653
A23: Avg RBC Charge (investable) | B23: SUMPRODUCT(weights, RBC%) | C23: =SUMPRODUCT(C6:C12,Inputs!E16:E22) -> 0.045812 | D23: =SUMPRODUCT(D6:D12,Inputs!E16:E22) -> 0.054719 | E23: =SUMPRODUCT(E6:E12,Inputs!E16:E22) -> 0.055367 | F23: =SUMPRODUCT(F6:F12,Inputs!E16:E22) -> 0.051128 | G23: =SUMPRODUCT(G6:G12,Inputs!E16:E22) -> 0.051911 | H23: =SUMPRODUCT(H6:H12,Inputs!E16:E22) -> 0.054719
A24: Solvency Efficiency (Ret÷RBC) | B24: Return ÷ Avg RBC Charge | C24: =IF(C23>0,C19/C23,0) -> 0.3032175 | D24: =IF(D23>0,D19/D23,0) -> 0.30249091 | E24: =IF(E23>0,E19/E23,0) -> 0.31368866 | F24: =IF(F23>0,F19/F23,0) -> 0.30454937 | G24: =IF(G23>0,G19/G23,0) -> 0.30602377 | H24: =IF(H23>0,H19/H23,0) -> 0.30249091
A25: TCR Base (mn) | B25: TCR_Ins + AvgRBC × AUM | C25: =Inputs!B8+C23*Inputs!B5 -> 988.996 | D25: =Inputs!B8+D23*Inputs!B5 -> 1060.252 | E25: =Inputs!B8+E23*Inputs!B5 -> 1065.436 | F25: =Inputs!B8+F23*Inputs!B5 -> 1031.524 | G25: =Inputs!B8+G23*Inputs!B5 -> 1037.788 | H25: =Inputs!B8+H23*Inputs!B5 -> 1060.252
A26: CAR Base (%) | B26: TCA ÷ TCR Base | C26: =Inputs!B7/C25 -> 2.1142654 | D26: =Inputs!B7/D25 -> 1.9721727 | E26: =Inputs!B7/E25 -> 1.9625768 | F26: =Inputs!B7/F25 -> 2.0270978 | G26: =Inputs!B7/G25 -> 2.0148624 | H26: =Inputs!B7/H25 -> 1.9721727
A28: C. VaR ANALYSIS (Parametric 99.5% | SUMPRODUCT formulas — no array formulas)
A29: Metric | B29: Formula | C29: Current SAA | D29: Port 1 | E29: Port 2 | F29: Port 3 | G29: Port 4 | H29: Custom
A30: 10-Day VaR % | B30: Z × SQRT(daily_var) × SQRT(10) | C30: =Inputs!B10*SQRT(C20)*SQRT(10) -> 0.0048463631 | D30: =Inputs!B10*SQRT(D20)*SQRT(10) -> 0.0067913961 | E30: =Inputs!B10*SQRT(E20)*SQRT(10) -> 0.0071943521 | F30: =Inputs!B10*SQRT(F20)*SQRT(10) -> 0.0058665166 | G30: =Inputs!B10*SQRT(G20)*SQRT(10) -> 0.0061496111 | H30: =Inputs!B10*SQRT(H20)*SQRT(10) -> 0.0067913961
A31: 10-Day VaR THB (mn) | B31: VaR% × AUM | C31: =C30*Inputs!B5 -> 38.770905 | D31: =D30*Inputs!B5 -> 54.331169 | E31: =E30*Inputs!B5 -> 57.554816 | F31: =F30*Inputs!B5 -> 46.932133 | G31: =G30*Inputs!B5 -> 49.196889 | H31: =H30*Inputs!B5 -> 54.331169
A32: 1-Year VaR % (parametric) | B32: Z × Annual SD [KKP uses historical — will differ] | C32: =Inputs!B10*C21 -> 0.02432855 | D32: =Inputs!B10*D21 -> 0.034092538 | E32: =Inputs!B10*E21 -> 0.036115361 | F32: =Inputs!B10*F21 -> 0.02944968 | G32: =Inputs!B10*G21 -> 0.030870803 | H32: =Inputs!B10*H21 -> 0.034092538
A33: 1-Year VaR THB (mn) | B33: VaR1y% × AUM [parametric, not historical] | C33: =C32*Inputs!B5 -> 194.6284 | D33: =D32*Inputs!B5 -> 272.7403 | E33: =E32*Inputs!B5 -> 288.92289 | F33: =F32*Inputs!B5 -> 235.59744 | G33: =G32*Inputs!B5 -> 246.96642 | H33: =H32*Inputs!B5 -> 272.7403
A34: P&L VaR (mn) [standalone] | B34: Σ Z×(SD_i/√252)×√10×wᵢ×AUM for GloFI,REIT,LocEq,GloEq | C34: =Inputs!B10*(Inputs!C19/SQRT(Inputs!B12))*SQRT(10)*C9*Inputs!B5+Inputs!B10*(Inputs!C20/SQRT(Inputs!B12))*SQRT(10)*C10*Inputs!B5+Inputs!B10*(Inputs!C21/SQRT(Inputs!B12))*SQRT(10)*C11*Inputs!B5+Inputs!B10*(Inputs!C22/SQRT(Inputs!B12))*SQRT(10)*C12*Inputs!B5 -> 23.912859 | D34: =Inputs!B10*(Inputs!C19/SQRT(Inputs!B12))*SQRT(10)*D9*Inputs!B5+Inputs!B10*(Inputs!C20/SQRT(Inputs!B12))*SQRT(10)*D10*Inputs!B5+Inputs!B10*(Inputs!C21/SQRT(Inputs!B12))*SQRT(10)*D11*Inputs!B5+Inputs!B10*(Inputs!C22/SQRT(Inputs!B12))*SQRT(10)*D12*Inputs!B5 -> 50.77326 | E34: =Inputs!B10*(Inputs!C19/SQRT(Inputs!B12))*SQRT(10)*E9*Inputs!B5+Inputs!B10*(Inputs!C20/SQRT(Inputs!B12))*SQRT(10)*E10*Inputs!B5+Inputs!B10*(Inputs!C21/SQRT(Inputs!B12))*SQRT(10)*E11*Inputs!B5+Inputs!B10*(Inputs!C22/SQRT(Inputs!B12))*SQRT(10)*E12*Inputs!B5 -> 61.80807 | F34: =Inputs!B10*(Inputs!C19/SQRT(Inputs!B12))*SQRT(10)*F9*Inputs!B5+Inputs!B10*(Inputs!C20/SQRT(Inputs!B12))*SQRT(10)*F10*Inputs!B5+Inputs!B10*(Inputs!C21/SQRT(Inputs!B12))*SQRT(10)*F11*Inputs!B5+Inputs!B10*(Inputs!C22/SQRT(Inputs!B12))*SQRT(10)*F12*Inputs!B5 -> 40.169498 | G34: =Inputs!B10*(Inputs!C19/SQRT(Inputs!B12))*SQRT(10)*G9*Inputs!B5+Inputs!B10*(Inputs!C20/SQRT(Inputs!B12))*SQRT(10)*G10*Inputs!B5+Inputs!B10*(Inputs!C21/SQRT(Inputs!B12))*SQRT(10)*G11*Inputs!B5+Inputs!B10*(Inputs!C22/SQRT(Inputs!B12))*SQRT(10)*G12*Inputs!B5 -> 44.048923 | H34: =Inputs!B10*(Inputs!C19/SQRT(Inputs!B12))*SQRT(10)*H9*Inputs!B5+Inputs!B10*(Inputs!C20/SQRT(Inputs!B12))*SQRT(10)*H10*Inputs!B5+Inputs!B10*(Inputs!C21/SQRT(Inputs!B12))*SQRT(10)*H11*Inputs!B5+Inputs!B10*(Inputs!C22/SQRT(Inputs!B12))*SQRT(10)*H12*Inputs!B5 -> 50.77326
A35: OCI VaR (mn) [DV01] | B35: Σ Dur×Z×(YldVol/√252)×√10×wᵢ×AUM for Gov,Corp | C35: =Inputs!B27*Inputs!B10*(Inputs!D27/SQRT(Inputs!B12))*SQRT(10)*C7*Inputs!B5+Inputs!B28*Inputs!B10*(Inputs!D28/SQRT(Inputs!B12))*SQRT(10)*C8*Inputs!B5 -> 50.789681 | D35: =Inputs!B27*Inputs!B10*(Inputs!D27/SQRT(Inputs!B12))*SQRT(10)*D7*Inputs!B5+Inputs!B28*Inputs!B10*(Inputs!D28/SQRT(Inputs!B12))*SQRT(10)*D8*Inputs!B5 -> 44.56618 | E35: =Inputs!B27*Inputs!B10*(Inputs!D27/SQRT(Inputs!B12))*SQRT(10)*E7*Inputs!B5+Inputs!B28*Inputs!B10*(Inputs!D28/SQRT(Inputs!B12))*SQRT(10)*E8*Inputs!B5 -> 42.989779 | F35: =Inputs!B27*Inputs!B10*(Inputs!D27/SQRT(Inputs!B12))*SQRT(10)*F7*Inputs!B5+Inputs!B28*Inputs!B10*(Inputs!D28/SQRT(Inputs!B12))*SQRT(10)*F8*Inputs!B5 -> 49.01623 | G35: =Inputs!B27*Inputs!B10*(Inputs!D27/SQRT(Inputs!B12))*SQRT(10)*G7*Inputs!B5+Inputs!B28*Inputs!B10*(Inputs!D28/SQRT(Inputs!B12))*SQRT(10)*G8*Inputs!B5 -> 47.267409 | H35: =Inputs!B27*Inputs!B10*(Inputs!D27/SQRT(Inputs!B12))*SQRT(10)*H7*Inputs!B5+Inputs!B28*Inputs!B10*(Inputs!D28/SQRT(Inputs!B12))*SQRT(10)*H8*Inputs!B5 -> 44.56618
A36: Total VaR (10d) uses correlation → lower than P&L+OCI standalone sum (diversification benefit). P&L VaR: FVPL assets (GlobalFI via fund, LocalREIT, LocalEq, GlobalEq). OCI VaR: DV01 method for FVOCI assets (Gov Bonds, Corp Bonds only).
A38: D. CAR STRESS | ΔTCR = Σ(VaR_standalone_i × RBC_i) per asset
A39: Step | B39: Formula | C39: Current SAA | D39: Port 1 | E39: Port 2 | F39: Port 3 | G39: Port 4 | H39: Custom
A40: TCA (fixed) | B40: From Inputs | C40: =Inputs!B7 -> 2091 | D40: =Inputs!B7 -> 2091 | E40: =Inputs!B7 -> 2091 | F40: =Inputs!B7 -> 2091 | G40: =Inputs!B7 -> 2091 | H40: =Inputs!B7 -> 2091
A41: − Total VaR 10d (mn) | B41: Correlated portfolio VaR | C41: =C31 -> 38.770905 | D41: =D31 -> 54.331169 | E41: =E31 -> 57.554816 | F41: =F31 -> 46.932133 | G41: =G31 -> 49.196889 | H41: =H31 -> 54.331169
A42: tca stressed (mn) | B42: TCA − VaR 10d | C42: =C40-C41 -> 2052.2291 | D42: =D40-D41 -> 2036.6688 | E42: =E40-E41 -> 2033.4452 | F42: =F40-F41 -> 2044.0679 | G42: =G40-G41 -> 2041.8031 | H42: =H40-H41 -> 2036.6688
A43: TCR Base (mn) | B43: TCR_Ins + AvgRBC × AUM | C43: =C25 -> 988.996 | D43: =D25 -> 1060.252 | E43: =E25 -> 1065.436 | F43: =F25 -> 1031.524 | G43: =G25 -> 1037.788 | H43: =H25 -> 1060.252
A44: − ΔTCR (mn) | B44: Σ(VaR_standalone_i × RBC_i) per asset | C44: =(Inputs!B10*(Inputs!C16/SQRT(Inputs!B12))*SQRT(10)*C6*Inputs!B5)*Inputs!E16+(Inputs!B10*(Inputs!C17/SQRT(Inputs!B12))*SQRT(10)*C7*Inputs!B5)*Inputs!E17+(Inputs!B10*(Inputs!C18/SQRT(Inputs!B12))*SQRT(10)*C8*Inputs!B5)*Inputs!E18+(Inputs!B10*(Inputs!C19/SQRT(Inputs!B12))*SQRT(10)*C9*Inputs!B5)*Inputs!E19+(Inputs!B10*(Inputs!C20/SQRT(Inputs!B12))*SQRT(10)*C10*Inputs!B5)*Inputs!E20+(Inputs!B10*(Inputs!C21/SQRT(Inputs!B12))*SQRT(10)*C11*Inputs!B5)*Inputs!E21+(Inputs!B10*(Inputs!C22/SQRT(Inputs!B12))*SQRT(10)*C12*Inputs!B5)*Inputs!E22 -> 5.5438423 | D44: =(Inputs!B10*(Inputs!C16/SQRT(Inputs!B12))*SQRT(10)*D6*Inputs!B5)*Inputs!E16+(Inputs!B10*(Inputs!C17/SQRT(Inputs!B12))*SQRT(10)*D7*Inputs!B5)*Inputs!E17+(Inputs!B10*(Inputs!C18/SQRT(Inputs!B12))*SQRT(10)*D8*Inputs!B5)*Inputs!E18+(Inputs!B10*(Inputs!C19/SQRT(Inputs!B12))*SQRT(10)*D9*Inputs!B5)*Inputs!E19+(Inputs!B10*(Inputs!C20/SQRT(Inputs!B12))*SQRT(10)*D10*Inputs!B5)*Inputs!E20+(Inputs!B10*(Inputs!C21/SQRT(Inputs!B12))*SQRT(10)*D11*Inputs!B5)*Inputs!E21+(Inputs!B10*(Inputs!C22/SQRT(Inputs!B12))*SQRT(10)*D12*Inputs!B5)*Inputs!E22 -> 12.604216 | E44: =(Inputs!B10*(Inputs!C16/SQRT(Inputs!B12))*SQRT(10)*E6*Inputs!B5)*Inputs!E16+(Inputs!B10*(Inputs!C17/SQRT(Inputs!B12))*SQRT(10)*E7*Inputs!B5)*Inputs!E17+(Inputs!B10*(Inputs!C18/SQRT(Inputs!B12))*SQRT(10)*E8*Inputs!B5)*Inputs!E18+(Inputs!B10*(Inputs!C19/SQRT(Inputs!B12))*SQRT(10)*E9*Inputs!B5)*Inputs!E19+(Inputs!B10*(Inputs!C20/SQRT(Inputs!B12))*SQRT(10)*E10*Inputs!B5)*Inputs!E20+(Inputs!B10*(Inputs!C21/SQRT(Inputs!B12))*SQRT(10)*E11*Inputs!B5)*Inputs!E21+(Inputs!B10*(Inputs!C22/SQRT(Inputs!B12))*SQRT(10)*E12*Inputs!B5)*Inputs!E22 -> 13.183543 | F44: =(Inputs!B10*(Inputs!C16/SQRT(Inputs!B12))*SQRT(10)*F6*Inputs!B5)*Inputs!E16+(Inputs!B10*(Inputs!C17/SQRT(Inputs!B12))*SQRT(10)*F7*Inputs!B5)*Inputs!E17+(Inputs!B10*(Inputs!C18/SQRT(Inputs!B12))*SQRT(10)*F8*Inputs!B5)*Inputs!E18+(Inputs!B10*(Inputs!C19/SQRT(Inputs!B12))*SQRT(10)*F9*Inputs!B5)*Inputs!E19+(Inputs!B10*(Inputs!C20/SQRT(Inputs!B12))*SQRT(10)*F10*Inputs!B5)*Inputs!E20+(Inputs!B10*(Inputs!C21/SQRT(Inputs!B12))*SQRT(10)*F11*Inputs!B5)*Inputs!E21+(Inputs!B10*(Inputs!C22/SQRT(Inputs!B12))*SQRT(10)*F12*Inputs!B5)*Inputs!E22 -> 9.8557926 | G44: =(Inputs!B10*(Inputs!C16/SQRT(Inputs!B12))*SQRT(10)*G6*Inputs!B5)*Inputs!E16+(Inputs!B10*(Inputs!C17/SQRT(Inputs!B12))*SQRT(10)*G7*Inputs!B5)*Inputs!E17+(Inputs!B10*(Inputs!C18/SQRT(Inputs!B12))*SQRT(10)*G8*Inputs!B5)*Inputs!E18+(Inputs!B10*(Inputs!C19/SQRT(Inputs!B12))*SQRT(10)*G9*Inputs!B5)*Inputs!E19+(Inputs!B10*(Inputs!C20/SQRT(Inputs!B12))*SQRT(10)*G10*Inputs!B5)*Inputs!E20+(Inputs!B10*(Inputs!C21/SQRT(Inputs!B12))*SQRT(10)*G11*Inputs!B5)*Inputs!E21+(Inputs!B10*(Inputs!C22/SQRT(Inputs!B12))*SQRT(10)*G12*Inputs!B5)*Inputs!E22 -> 10.451459 | H44: =(Inputs!B10*(Inputs!C16/SQRT(Inputs!B12))*SQRT(10)*H6*Inputs!B5)*Inputs!E16+(Inputs!B10*(Inputs!C17/SQRT(Inputs!B12))*SQRT(10)*H7*Inputs!B5)*Inputs!E17+(Inputs!B10*(Inputs!C18/SQRT(Inputs!B12))*SQRT(10)*H8*Inputs!B5)*Inputs!E18+(Inputs!B10*(Inputs!C19/SQRT(Inputs!B12))*SQRT(10)*H9*Inputs!B5)*Inputs!E19+(Inputs!B10*(Inputs!C20/SQRT(Inputs!B12))*SQRT(10)*H10*Inputs!B5)*Inputs!E20+(Inputs!B10*(Inputs!C21/SQRT(Inputs!B12))*SQRT(10)*H11*Inputs!B5)*Inputs!E21+(Inputs!B10*(Inputs!C22/SQRT(Inputs!B12))*SQRT(10)*H12*Inputs!B5)*Inputs!E22 -> 12.604216
...
